Workbook

Sheet Cover
B2: ENERGY SECTOR — SENIOR QUANT RESEARCH
B3: CEG · VST · CCJ — Benchmark, Factor, Optimization & Monte-Carlo Framework
B5: Independent Power Producers & Nuclear Fuel — AI/Data-Center Power Demand Thematic
B7: Report date: | D7: 2026-10-01
B8: Coverage window: | D8: Jan-2025 – Sep-2026 (trailing), fwd view to FY2027
B9: Prepared for: | D9: xristos.katsambas@gmail.com
B10: Classification: | D10: Internal research workbook — not a solicitation
B14: WHAT'S NEW IN THIS VERSION (vs. the original workbook)
B15: ✓ XLE sector benchmark added — alpha, tracking error, information ratio, up/down capture
B16: ✓ Macro factor sensitivities — single-factor betas to WTI crude, Henry Hub gas, uranium spot, 10Y yield
B17: ✓ Real running-peak max drawdown (replaces the MIN/MAX proxy) + historical VaR/CVaR (95%/99%) + skew/kurtosis
B18: ✓ Sortino ratio (downside deviation) alongside Sharpe
B19: ✓ Mean-variance portfolio optimization — 66-point efficient frontier, max-Sharpe & min-vol portfolios identified
B20: ✓ Monte Carlo simulation (10,000 paths, 12-month horizon) — percentile fan chart, terminal-value histogram, simulation-based VaR/CVaR
B21: ✓ Companion Python repo (src/) for full reproducibility: fetch_data.py, monte_carlo.py, build_workbook.py
B23: WORKBOOK MAP
B24: 1. Cover | C24: This page — scope, what's new, disclaimers
B25: 2. Market Data | C25: Monthly levels: CEG/VST/CCJ/XLE + WTI, Henry Hub, 10Y yield, uranium spot — sourced
B26: 3. Returns & Risk | C26: Returns, real drawdown, Sharpe/Sortino, VaR/CVaR, skew/kurtosis — live formulas
B27: 4. Benchmark & Factors | C27: Alpha/beta/TE/IR/capture vs. XLE; univariate betas to oil/gas/uranium/rates
B28: 5. Portfolio Optimization | C28: 66-point efficient frontier, max-Sharpe & min-variance portfolios, CML
B29: 6. Monte Carlo | C29: 10,000-path simulation: percentile fan, terminal histogram, sim VaR/CVaR
B30: 7-9. Deep Dives | C30: CEG / VST / CCJ — fundamentals, technicals, catalysts, earnings history
B31: 10. Catalyst Calendar | C31: Consolidated dated events, Oct-2026–Q1-2027
B32: 11. Recommendation | C32: Optimizer + simulation-informed sizing, scenario framing, disclaimer
B35: METHODOLOGY & LIMITATIONS (read before using any number in this workbook): Monthly observation frequency (21 months) is a THIN sample for statistical inference — covariance, VaR, skew/kurtosis and regression betas all carry wide estimation error at n=20. Max drawdown, VaR/CVaR and correlation use month-end data only and will UNDERSTATE true intra-month peak-to-trough risk. Macro factor betas are univariate (one factor at a time) — true multi-factor attribution requires controlling for collinearity among oil/gas/uranium/rates, which is a job for proper regression software, not single-variable Excel formulas; treat these as directional, not precise. The Monte Carlo simulation assumes i.i.d. multivariate-normal monthly returns — it does not capture fat tails, regime shifts, or autocorrelation, and is a shape-of-uncertainty illustration, not a forecast. WTI and uranium monthly series are analyst-reconstructed approximations (see Market Data sourcing note); XLE, Henry Hub, and 10Y yield are sourced from public data providers. This is NOT investment advice or a broker-dealer research report. Verify every figure against a live terminal before acting.
A43: READ-ONLY COPY. © 2026 Christos Katsampas. All rights reserved. Viewing is permitted; copying, editing or redistribution without written permission is prohibited.

Sheet Market Data
A1: MONTHLY MARKET DATA — Prices, Benchmark & Macro Factors (Jan-2025 – Sep-2026)
A2: Month | B2: CEG | C2: VST | D2: CCJ | E2: XLE | F2: WTI | G2: Henry Hub | H2: UST 10Y | I2: Uranium
A3: Jan-25 | B3: 296.99 | C3: 166.66 | D3: 49.34 | E3: 41.83 | F3: 73 | G3: 4.13 | H3: 4.63 | I3: 73
A4: Feb-25 | B4: 248.05 | C4: 132.57 | D4: 43.95 | E4: 43.43 | F4: 71 | G4: 4.19 | H4: 4.45 | I4: 69.5
A5: Mar-25 | B5: 199.99 | C5: 116.68 | D5: 41.08 | E5: 44.95 | F5: 68.5 | G5: 4.12 | H5: 4.28 | I5: 66
A6: Apr-25 | B6: 221.63 | C6: 128.79 | D6: 45.06 | E6: 38.72 | F6: 63 | G6: 3.42 | H6: 4.28 | I6: 64.5
A7: May-25 | B7: 304.08 | C7: 159.54 | D7: 58.42 | E7: 39.22 | F7: 61.5 | G7: 3.12 | H7: 4.42 | I7: 68
A8: Jun-25 | B8: 320.58 | C8: 192.8 | D8: 74.09 | E8: 41.12 | F8: 65 | G8: 3.02 | H8: 4.38 | I8: 71.5
A9: Jul-25 | B9: 345.49 | C9: 207.46 | D9: 74.78 | E9: 42.29 | F9: 67 | G9: 3.2 | H9: 4.39 | I9: 73
A10: Aug-25 | B10: 306.27 | C10: 188.13 | D10: 77.24 | E10: 43.83 | F10: 64.5 | G10: 2.91 | H10: 4.26 | I10: 75.5
A11: Sep-25 | B11: 327.24 | C11: 195.11 | D11: 83.7 | E11: 43.69 | F11: 63.5 | G11: 2.97 | H11: 4.12 | I11: 78
A12: Oct-25 | B12: 374.9 | C12: 187.52 | D12: 102.01 | E12: 43.1 | F12: 61 | G12: 3.19 | H12: 4.06 | I12: 80.5
A13: Nov-25 | B13: 362.75 | C13: 178.12 | D13: 88.34 | E13: 44.23 | F13: 59.5 | G13: 3.79 | H13: 4.09 | I13: 79
A14: Dec-25 | B14: 351.71 | C14: 160.89 | D14: 91.49 | E14: 44.1 | F14: 58 | G14: 4.26 | H14: 4.14 | I14: 81
... A26: Spot (2026-10-01, intraday) | B26: 264.58 | C26: 139.05 | D26: 87.39 | E26: 61.8 | F26: 62 | G26: 2.85 | H26: 4.98 | I26: 89.45
A28: Sources: CEG/VST/CCJ — digrin.com, StockAnalysis.com, Yahoo Finance, Robinhood (retrieved 2026-10-01). XLE — digrin.com monthly closes. Henry Hub natural gas spot ($/MMBtu) — U.S. EIA (eia.gov/dnav/ng), Sep-2026 value estimated (not yet published at report date). UST 10Y — multpl.com monthly averages, cross-checked against market commentary for Sep-2026. Uranium spot (U3O8, $/lb) — Sep-2026 value sourced from Trading Economics; Jan-2025–Aug-2026 are ANALYST-RECONSTRUCTED APPROXIMATIONS consistent with the publicly reported direction of the uranium market (IMF/NUEXCO series not independently reproducible here) — replace with a UxC/TradeTech subscription feed before relying on these for the Uranium factor column. WTI crude ($/bbl) is similarly an ANALYST-RECONSTRUCTED APPROXIMATION based on EIA STEO commentary (direct EIA/FRED time-series endpoints were not reachable from this environment) — replace with a live feed (EIA, Bloomberg, FactSet) before using the Oil factor column for anything beyond directional illustration.

Sheet Returns & Risk
A1: RETURNS & RISK METRICS — live formulas, linked to Market Data
A2: Month | B2: CEG | C2: VST | D2: CCJ | E2: XLE | G2: WTI %chg | H2: HH %chg | I2: UST10Y Δ | J2: Uranium %chg | L2: CEG dwn² | M2: VST dwn² | N2: CCJ dwn²
A4: ='Market Data'!A4 | B4: =('Market Data'!B4/'Market Data'!B3)-1 | C4: =('Market Data'!C4/'Market Data'!C3)-1 | D4: =('Market Data'!D4/'Market Data'!D3)-1 | E4: =('Market Data'!E4/'Market Data'!E3)-1 | G4: =('Market Data'!F4/'Market Data'!F3)-1 | H4: =('Market Data'!G4/'Market Data'!G3)-1 | I4: =('Market Data'!H4-'Market Data'!H3) | J4: =('Market Data'!I4/'Market Data'!I3)-1 | L4: =MIN(B4,0)^2 | M4: =MIN(C4,0)^2 | N4: =MIN(D4,0)^2
A5: ='Market Data'!A5 | B5: =('Market Data'!B5/'Market Data'!B4)-1 | C5: =('Market Data'!C5/'Market Data'!C4)-1 | D5: =('Market Data'!D5/'Market Data'!D4)-1 | E5: =('Market Data'!E5/'Market Data'!E4)-1 | G5: =('Market Data'!F5/'Market Data'!F4)-1 | H5: =('Market Data'!G5/'Market Data'!G4)-1 | I5: =('Market Data'!H5-'Market Data'!H4) | J5: =('Market Data'!I5/'Market Data'!I4)-1 | L5: =MIN(B5,0)^2 | M5: =MIN(C5,0)^2 | N5: =MIN(D5,0)^2
A6: ='Market Data'!A6 | B6: =('Market Data'!B6/'Market Data'!B5)-1 | C6: =('Market Data'!C6/'Market Data'!C5)-1 | D6: =('Market Data'!D6/'Market Data'!D5)-1 | E6: =('Market Data'!E6/'Market Data'!E5)-1 | G6: =('Market Data'!F6/'Market Data'!F5)-1 | H6: =('Market Data'!G6/'Market Data'!G5)-1 | I6: =('Market Data'!H6-'Market Data'!H5) | J6: =('Market Data'!I6/'Market Data'!I5)-1 | L6: =MIN(B6,0)^2 | M6: =MIN(C6,0)^2 | N6: =MIN(D6,0)^2
A7: ='Market Data'!A7 | B7: =('Market Data'!B7/'Market Data'!B6)-1 | C7: =('Market Data'!C7/'Market Data'!C6)-1 | D7: =('Market Data'!D7/'Market Data'!D6)-1 | E7: =('Market Data'!E7/'Market Data'!E6)-1 | G7: =('Market Data'!F7/'Market Data'!F6)-1 | H7: =('Market Data'!G7/'Market Data'!G6)-1 | I7: =('Market Data'!H7-'Market Data'!H6) | J7: =('Market Data'!I7/'Market Data'!I6)-1 | L7: =MIN(B7,0)^2 | M7: =MIN(C7,0)^2 | N7: =MIN(D7,0)^2
A8: ='Market Data'!A8 | B8: =('Market Data'!B8/'Market Data'!B7)-1 | C8: =('Market Data'!C8/'Market Data'!C7)-1 | D8: =('Market Data'!D8/'Market Data'!D7)-1 | E8: =('Market Data'!E8/'Market Data'!E7)-1 | G8: =('Market Data'!F8/'Market Data'!F7)-1 | H8: =('Market Data'!G8/'Market Data'!G7)-1 | I8: =('Market Data'!H8-'Market Data'!H7) | J8: =('Market Data'!I8/'Market Data'!I7)-1 | L8: =MIN(B8,0)^2 | M8: =MIN(C8,0)^2 | N8: =MIN(D8,0)^2
A9: ='Market Data'!A9 | B9: =('Market Data'!B9/'Market Data'!B8)-1 | C9: =('Market Data'!C9/'Market Data'!C8)-1 | D9: =('Market Data'!D9/'Market Data'!D8)-1 | E9: =('Market Data'!E9/'Market Data'!E8)-1 | G9: =('Market Data'!F9/'Market Data'!F8)-1 | H9: =('Market Data'!G9/'Market Data'!G8)-1 | I9: =('Market Data'!H9-'Market Data'!H8) | J9: =('Market Data'!I9/'Market Data'!I8)-1 | L9: =MIN(B9,0)^2 | M9: =MIN(C9,0)^2 | N9: =MIN(D9,0)^2
A10: ='Market Data'!A10 | B10: =('Market Data'!B10/'Market Data'!B9)-1 | C10: =('Market Data'!C10/'Market Data'!C9)-1 | D10: =('Market Data'!D10/'Market Data'!D9)-1 | E10: =('Market Data'!E10/'Market Data'!E9)-1 | G10: =('Market Data'!F10/'Market Data'!F9)-1 | H10: =('Market Data'!G10/'Market Data'!G9)-1 | I10: =('Market Data'!H10-'Market Data'!H9) | J10: =('Market Data'!I10/'Market Data'!I9)-1 | L10: =MIN(B10,0)^2 | M10: =MIN(C10,0)^2 | N10: =MIN(D10,0)^2
A11: ='Market Data'!A11 | B11: =('Market Data'!B11/'Market Data'!B10)-1 | C11: =('Market Data'!C11/'Market Data'!C10)-1 | D11: =('Market Data'!D11/'Market Data'!D10)-1 | E11: =('Market Data'!E11/'Market Data'!E10)-1 | G11: =('Market Data'!F11/'Market Data'!F10)-1 | H11: =('Market Data'!G11/'Market Data'!G10)-1 | I11: =('Market Data'!H11-'Market Data'!H10) | J11: =('Market Data'!I11/'Market Data'!I10)-1 | L11: =MIN(B11,0)^2 | M11: =MIN(C11,0)^2 | N11: =MIN(D11,0)^2
A12: ='Market Data'!A12 | B12: =('Market Data'!B12/'Market Data'!B11)-1 | C12: =('Market Data'!C12/'Market Data'!C11)-1 | D12: =('Market Data'!D12/'Market Data'!D11)-1 | E12: =('Market Data'!E12/'Market Data'!E11)-1 | G12: =('Market Data'!F12/'Market Data'!F11)-1 | H12: =('Market Data'!G12/'Market Data'!G11)-1 | I12: =('Market Data'!H12-'Market Data'!H11) | J12: =('Market Data'!I12/'Market Data'!I11)-1 | L12: =MIN(B12,0)^2 | M12: =MIN(C12,0)^2 | N12: =MIN(D12,0)^2
A13: ='Market Data'!A13 | B13: =('Market Data'!B13/'Market Data'!B12)-1 | C13: =('Market Data'!C13/'Market Data'!C12)-1 | D13: =('Market Data'!D13/'Market Data'!D12)-1 | E13: =('Market Data'!E13/'Market Data'!E12)-1 | G13: =('Market Data'!F13/'Market Data'!F12)-1 | H13: =('Market Data'!G13/'Market Data'!G12)-1 | I13: =('Market Data'!H13-'Market Data'!H12) | J13: =('Market Data'!I13/'Market Data'!I12)-1 | L13: =MIN(B13,0)^2 | M13: =MIN(C13,0)^2 | N13: =MIN(D13,0)^2
A14: ='Market Data'!A14 | B14: =('Market Data'!B14/'Market Data'!B13)-1 | C14: =('Market Data'!C14/'Market Data'!C13)-1 | D14: =('Market Data'!D14/'Market Data'!D13)-1 | E14: =('Market Data'!E14/'Market Data'!E13)-1 | G14: =('Market Data'!F14/'Market Data'!F13)-1 | H14: =('Market Data'!G14/'Market Data'!G13)-1 | I14: =('Market Data'!H14-'Market Data'!H13) | J14: =('Market Data'!I14/'Market Data'!I13)-1 | L14: =MIN(B14,0)^2 | M14: =MIN(C14,0)^2 | N14: =MIN(D14,0)^2
A15: ='Market Data'!A15 | B15: =('Market Data'!B15/'Market Data'!B14)-1 | C15: =('Market Data'!C15/'Market Data'!C14)-1 | D15: =('Market Data'!D15/'Market Data'!D14)-1 | E15: =('Market Data'!E15/'Market Data'!E14)-1 | G15: =('Market Data'!F15/'Market Data'!F14)-1 | H15: =('Market Data'!G15/'Market Data'!G14)-1 | I15: =('Market Data'!H15-'Market Data'!H14) | J15: =('Market Data'!I15/'Market Data'!I14)-1 | L15: =MIN(B15,0)^2 | M15: =MIN(C15,0)^2 | N15: =MIN(D15,0)^2
... A23: ='Market Data'!A23 | B23: =('Market Data'!B23/'Market Data'!B22)-1 | C23: =('Market Data'!C23/'Market Data'!C22)-1 | D23: =('Market Data'!D23/'Market Data'!D22)-1 | E23: =('Market Data'!E23/'Market Data'!E22)-1 | G23: =('Market Data'!F23/'Market Data'!F22)-1 | H23: =('Market Data'!G23/'Market Data'!G22)-1 | I23: =('Market Data'!H23-'Market Data'!H22) | J23: =('Market Data'!I23/'Market Data'!I22)-1 | L23: =MIN(B23,0)^2 | M23: =MIN(C23,0)^2 | N23: =MIN(D23,0)^2
A26: DRAWDOWN DETAIL — running-peak method (real max drawdown, monthly granularity)
A27: Month | B27: CEG Px | C27: CEG RunMax | D27: CEG DD | E27: VST Px | F27: VST RunMax | G27: VST DD | H27: CCJ Px | I27: CCJ RunMax | J27: CCJ DD
A28: ='Market Data'!A3 | B28: ='Market Data'!B3 | C28: =B28 | D28: =(B28/C28)-1 | E28: ='Market Data'!C3 | F28: =E28 | G28: =(E28/F28)-1 | H28: ='Market Data'!D3 | I28: =H28 | J28: =(H28/I28)-1
A29: ='Market Data'!A4 | B29: ='Market Data'!B4 | C29: =MAX(C28,B29) | D29: =(B29/C29)-1 | E29: ='Market Data'!C4 | F29: =MAX(F28,E29) | G29: =(E29/F29)-1 | H29: ='Market Data'!D4 | I29: =MAX(I28,H29) | J29: =(H29/I29)-1
A30: ='Market Data'!A5 | B30: ='Market Data'!B5 | C30: =MAX(C29,B30) | D30: =(B30/C30)-1 | E30: ='Market Data'!C5 | F30: =MAX(F29,E30) | G30: =(E30/F30)-1 | H30: ='Market Data'!D5 | I30: =MAX(I29,H30) | J30: =(H30/I30)-1
A31: ='Market Data'!A6 | B31: ='Market Data'!B6 | C31: =MAX(C30,B31) | D31: =(B31/C31)-1 | E31: ='Market Data'!C6 | F31: =MAX(F30,E31) | G31: =(E31/F31)-1 | H31: ='Market Data'!D6 | I31: =MAX(I30,H31) | J31: =(H31/I31)-1
A32: ='Market Data'!A7 | B32: ='Market Data'!B7 | C32: =MAX(C31,B32) | D32: =(B32/C32)-1 | E32: ='Market Data'!C7 | F32: =MAX(F31,E32) | G32: =(E32/F32)-1 | H32: ='Market Data'!D7 | I32: =MAX(I31,H32) | J32: =(H32/I32)-1
A33: ='Market Data'!A8 | B33: ='Market Data'!B8 | C33: =MAX(C32,B33) | D33: =(B33/C33)-1 | E33: ='Market Data'!C8 | F33: =MAX(F32,E33) | G33: =(E33/F33)-1 | H33: ='Market Data'!D8 | I33: =MAX(I32,H33) | J33: =(H33/I33)-1
A34: ='Market Data'!A9 | B34: ='Market Data'!B9 | C34: =MAX(C33,B34) | D34: =(B34/C34)-1 | E34: ='Market Data'!C9 | F34: =MAX(F33,E34) | G34: =(E34/F34)-1 | H34: ='Market Data'!D9 | I34: =MAX(I33,H34) | J34: =(H34/I34)-1
A35: ='Market Data'!A10 | B35: ='Market Data'!B10 | C35: =MAX(C34,B35) | D35: =(B35/C35)-1 | E35: ='Market Data'!C10 | F35: =MAX(F34,E35) | G35: =(E35/F35)-1 | H35: ='Market Data'!D10 | I35: =MAX(I34,H35) | J35: =(H35/I35)-1
A36: ='Market Data'!A11 | B36: ='Market Data'!B11 | C36: =MAX(C35,B36) | D36: =(B36/C36)-1 | E36: ='Market Data'!C11 | F36: =MAX(F35,E36) | G36: =(E36/F36)-1 | H36: ='Market Data'!D11 | I36: =MAX(I35,H36) | J36: =(H36/I36)-1
A37: ='Market Data'!A12 | B37: ='Market Data'!B12 | C37: =MAX(C36,B37) | D37: =(B37/C37)-1 | E37: ='Market Data'!C12 | F37: =MAX(F36,E37) | G37: =(E37/F37)-1 | H37: ='Market Data'!D12 | I37: =MAX(I36,H37) | J37: =(H37/I37)-1
A38: ='Market Data'!A13 | B38: ='Market Data'!B13 | C38: =MAX(C37,B38) | D38: =(B38/C38)-1 | E38: ='Market Data'!C13 | F38: =MAX(F37,E38) | G38: =(E38/F38)-1 | H38: ='Market Data'!D13 | I38: =MAX(I37,H38) | J38: =(H38/I38)-1
A39: ='Market Data'!A14 | B39: ='Market Data'!B14 | C39: =MAX(C38,B39) | D39: =(B39/C39)-1 | E39: ='Market Data'!C14 | F39: =MAX(F38,E39) | G39: =(E39/F39)-1 | H39: ='Market Data'!D14 | I39: =MAX(I38,H39) | J39: =(H39/I39)-1
A40: ='Market Data'!A15 | B40: ='Market Data'!B15 | C40: =MAX(C39,B40) | D40: =(B40/C40)-1 | E40: ='Market Data'!C15 | F40: =MAX(F39,E40) | G40: =(E40/F40)-1 | H40: ='Market Data'!D15 | I40: =MAX(I39,H40) | J40: =(H40/I40)-1
... A48: ='Market Data'!A23 | B48: ='Market Data'!B23 | C48: =MAX(C47,B48) | D48: =(B48/C48)-1 | E48: ='Market Data'!C23 | F48: =MAX(F47,E48) | G48: =(E48/F48)-1 | H48: ='Market Data'!D23 | I48: =MAX(I47,H48) | J48: =(H48/I48)-1
A50: SUMMARY RISK & RETURN STATISTICS
A51: Metric | B51: CEG | C51: VST | D51: CCJ | E51: XLE
A52: Risk-free rate (annual, input) | B52: 0.043
A53: Mean monthly return | B53: =AVERAGE(B4:B23) | C53: =AVERAGE(C4:C23) | D53: =AVERAGE(D4:D23) | E53: =AVERAGE(E4:E23)
A54: Std dev, monthly | B54: =STDEV(B4:B23) | C54: =STDEV(C4:C23) | D54: =STDEV(D4:D23) | E54: =STDEV(E4:E23)
A55: Annualized return (CAGR) | B55: =('Market Data'!B23/'Market Data'!B3)^(12/20)-1 | C55: =('Market Data'!C23/'Market Data'!C3)^(12/20)-1 | D55: =('Market Data'!D23/'Market Data'!D3)^(12/20)-1 | E55: =('Market Data'!E23/'Market Data'!E3)^(12/20)-1
A56: Annualized volatility | B56: =B54*SQRT(12) | C56: =C54*SQRT(12) | D56: =D54*SQRT(12) | E56: =E54*SQRT(12)
A57: Max drawdown (real, running-peak) | B57: =MIN(D28:D48) | C57: =MIN(G28:G48) | D57: =MIN(J28:J48) | E57: ="n/a"
A58: Skewness (monthly returns) | B58: =SKEW(B4:B23) | C58: =SKEW(C4:C23) | D58: =SKEW(D4:D23) | E58: =SKEW(E4:E23)
...

Sheet Benchmark & Factors
A1: BENCHMARK & MACRO FACTOR ANALYSIS — single-factor regressions, linked to Returns & Risk
K2: CEG-XLE | L2: VST-XLE | M2: CCJ-XLE
A3: TABLE A — RELATIVE TO XLE (SECTOR BENCHMARK)
A4: Ticker | B4: Beta (XLE) | C4: R² | D4: Alpha (ann., Jensen) | E4: Tracking Error (ann.) | F4: Info Ratio | G4: Up Capture | H4: Down Capture | K4: ='Returns & Risk'!B4-'Returns & Risk'!E4 | L4: ='Returns & Risk'!C4-'Returns & Risk'!E4 | M4: ='Returns & Risk'!D4-'Returns & Risk'!E4
A5: CEG | B5: =SLOPE('Returns & Risk'!B4:B23,'Returns & Risk'!E4:E23) | C5: =RSQ('Returns & Risk'!B4:B23,'Returns & Risk'!E4:E23) | D5: ='Returns & Risk'!B55-('Returns & Risk'!$B$52+B5*('Returns & Risk'!E55-'Returns & Risk'!$B$52)) | E5: =STDEV(K4:K23)*SQRT(12) | F5: =('Returns & Risk'!B55-'Returns & Risk'!E55)/E5 | G5: =AVERAGEIF('Returns & Risk'!E4:E23,">0",'Returns & Risk'!B4:B23)/AVERAGEIF('Returns & Risk'!E4:E23,">0",'Returns & Risk'!E4:E23) | H5: =AVERAGEIF('Returns & Risk'!E4:E23,"<0",'Returns & Risk'!B4:B23)/AVERAGEIF('Returns & Risk'!E4:E23,"<0",'Returns & Risk'!E4:E23) | K5: ='Returns & Risk'!B5-'Returns & Risk'!E5 | L5: ='Returns & Risk'!C5-'Returns & Risk'!E5 | M5: ='Returns & Risk'!D5-'Returns & Risk'!E5
A6: VST | B6: =SLOPE('Returns & Risk'!C4:C23,'Returns & Risk'!E4:E23) | C6: =RSQ('Returns & Risk'!C4:C23,'Returns & Risk'!E4:E23) | D6: ='Returns & Risk'!C55-('Returns & Risk'!$B$52+B6*('Returns & Risk'!E55-'Returns & Risk'!$B$52)) | E6: =STDEV(L4:L23)*SQRT(12) | F6: =('Returns & Risk'!C55-'Returns & Risk'!E55)/E6 | G6: =AVERAGEIF('Returns & Risk'!E4:E23,">0",'Returns & Risk'!C4:C23)/AVERAGEIF('Returns & Risk'!E4:E23,">0",'Returns & Risk'!E4:E23) | H6: =AVERAGEIF('Returns & Risk'!E4:E23,"<0",'Returns & Risk'!C4:C23)/AVERAGEIF('Returns & Risk'!E4:E23,"<0",'Returns & Risk'!E4:E23) | K6: ='Returns & Risk'!B6-'Returns & Risk'!E6 | L6: ='Returns & Risk'!C6-'Returns & Risk'!E6 | M6: ='Returns & Risk'!D6-'Returns & Risk'!E6
A7: CCJ | B7: =SLOPE('Returns & Risk'!D4:D23,'Returns & Risk'!E4:E23) | C7: =RSQ('Returns & Risk'!D4:D23,'Returns & Risk'!E4:E23) | D7: ='Returns & Risk'!D55-('Returns & Risk'!$B$52+B7*('Returns & Risk'!E55-'Returns & Risk'!$B$52)) | E7: =STDEV(M4:M23)*SQRT(12) | F7: =('Returns & Risk'!D55-'Returns & Risk'!E55)/E7 | G7: =AVERAGEIF('Returns & Risk'!E4:E23,">0",'Returns & Risk'!D4:D23)/AVERAGEIF('Returns & Risk'!E4:E23,">0",'Returns & Risk'!E4:E23) | H7: =AVERAGEIF('Returns & Risk'!E4:E23,"<0",'Returns & Risk'!D4:D23)/AVERAGEIF('Returns & Risk'!E4:E23,"<0",'Returns & Risk'!E4:E23) | K7: ='Returns & Risk'!B7-'Returns & Risk'!E7 | L7: ='Returns & Risk'!C7-'Returns & Risk'!E7 | M7: ='Returns & Risk'!D7-'Returns & Risk'!E7
K8: ='Returns & Risk'!B8-'Returns & Risk'!E8 | L8: ='Returns & Risk'!C8-'Returns & Risk'!E8 | M8: ='Returns & Risk'!D8-'Returns & Risk'!E8
A9: TABLE B — MACRO FACTOR SENSITIVITIES (univariate SLOPE/R², one factor at a time) | K9: ='Returns & Risk'!B9-'Returns & Risk'!E9 | L9: ='Returns & Risk'!C9-'Returns & Risk'!E9 | M9: ='Returns & Risk'!D9-'Returns & Risk'!E9
A10: Ticker | B10: β Oil (WTI) | C10: R² | D10: β Nat Gas (HH) | E10: R² | F10: β Uranium | G10: R² | H10: β Rates (10Y Δ) | I10: R² | K10: ='Returns & Risk'!B10-'Returns & Risk'!E10 | L10: ='Returns & Risk'!C10-'Returns & Risk'!E10 | M10: ='Returns & Risk'!D10-'Returns & Risk'!E10
A11: CEG | B11: =SLOPE('Returns & Risk'!B4:B23,'Returns & Risk'!G4:G23) | C11: =RSQ('Returns & Risk'!B4:B23,'Returns & Risk'!G4:G23) | D11: =SLOPE('Returns & Risk'!B4:B23,'Returns & Risk'!H4:H23) | E11: =RSQ('Returns & Risk'!B4:B23,'Returns & Risk'!H4:H23) | F11: =SLOPE('Returns & Risk'!B4:B23,'Returns & Risk'!J4:J23) | G11: =RSQ('Returns & Risk'!B4:B23,'Returns & Risk'!J4:J23) | H11: =SLOPE('Returns & Risk'!B4:B23,'Returns & Risk'!I4:I23) | I11: =RSQ('Returns & Risk'!B4:B23,'Returns & Risk'!I4:I23) | K11: ='Returns & Risk'!B11-'Returns & Risk'!E11 | L11: ='Returns & Risk'!C11-'Returns & Risk'!E11 | M11: ='Returns & Risk'!D11-'Returns & Risk'!E11
A12: VST | B12: =SLOPE('Returns & Risk'!C4:C23,'Returns & Risk'!G4:G23) | C12: =RSQ('Returns & Risk'!C4:C23,'Returns & Risk'!G4:G23) | D12: =SLOPE('Returns & Risk'!C4:C23,'Returns & Risk'!H4:H23) | E12: =RSQ('Returns & Risk'!C4:C23,'Returns & Risk'!H4:H23) | F12: =SLOPE('Returns & Risk'!C4:C23,'Returns & Risk'!J4:J23) | G12: =RSQ('Returns & Risk'!C4:C23,'Returns & Risk'!J4:J23) | H12: =SLOPE('Returns & Risk'!C4:C23,'Returns & Risk'!I4:I23) | I12: =RSQ('Returns & Risk'!C4:C23,'Returns & Risk'!I4:I23) | K12: ='Returns & Risk'!B12-'Returns & Risk'!E12 | L12: ='Returns & Risk'!C12-'Returns & Risk'!E12 | M12: ='Returns & Risk'!D12-'Returns & Risk'!E12
A13: CCJ | B13: =SLOPE('Returns & Risk'!D4:D23,'Returns & Risk'!G4:G23) | C13: =RSQ('Returns & Risk'!D4:D23,'Returns & Risk'!G4:G23) | D13: =SLOPE('Returns & Risk'!D4:D23,'Returns & Risk'!H4:H23) | E13: =RSQ('Returns & Risk'!D4:D23,'Returns & Risk'!H4:H23) | F13: =SLOPE('Returns & Risk'!D4:D23,'Returns & Risk'!J4:J23) | G13: =RSQ('Returns & Risk'!D4:D23,'Returns & Risk'!J4:J23) | H13: =SLOPE('Returns & Risk'!D4:D23,'Returns & Risk'!I4:I23) | I13: =RSQ('Returns & Risk'!D4:D23,'Returns & Risk'!I4:I23) | K13: ='Returns & Risk'!B13-'Returns & Risk'!E13 | L13: ='Returns & Risk'!C13-'Returns & Risk'!E13 | M13: ='Returns & Risk'!D13-'Returns & Risk'!E13
K14: ='Returns & Risk'!B14-'Returns & Risk'!E14 | L14: ='Returns & Risk'!C14-'Returns & Risk'!E14 | M14: ='Returns & Risk'!D14-'Returns & Risk'!E14
K15: ='Returns & Risk'!B15-'Returns & Risk'!E15 | L15: ='Returns & Risk'!C15-'Returns & Risk'!E15 | M15: ='Returns & Risk'!D15-'Returns & Risk'!E15
A16: Reading this tab: Beta(XLE) > 1 means the stock amplifies sector moves; Alpha is the annualized excess return left over after stripping out that market-beta exposure (CAPM/Jensen's alpha) — a positive alpha means the stock did better than its sector-beta alone would predict. Information Ratio is alpha per unit of tracking error — the standard buy-side measure of whether active risk is being paid for. Up/Down Capture above 1.0 in Up and below 1.0 in Down is the textbook 'asymmetric' profile a long-only holder wants. Table B betas are univariate (each factor regressed alone) because oil, gas, uranium and rates are themselves correlated, so a true multi-factor model would need to control for that collinearity — treat these as directional signals of sensitivity, not precise, independent exposures.
K21: ='Returns & Risk'!B21-'Returns & Risk'!E21 | L21: ='Returns & Risk'!C21-'Returns & Risk'!E21 | M21: ='Returns & Risk'!D21-'Returns & Risk'!E21
K22: ='Returns & Risk'!B22-'Returns & Risk'!E22 | L22: ='Returns & Risk'!C22-'Returns & Risk'!E22 | M22: ='Returns & Risk'!D22-'Returns & Risk'!E22
K23: ='Returns & Risk'!B23-'Returns & Risk'!E23 | L23: ='Returns & Risk'!C23-'Returns & Risk'!E23 | M23: ='Returns & Risk'!D23-'Returns & Risk'!E23

Sheet Portfolio Optimization
A1: PORTFOLIO OPTIMIZATION — Mean-Variance Efficient Frontier (CEG / VST / CCJ)
A3: MONTHLY COVARIANCE MATRIX (sample, n-1)
B4: CEG | C4: VST | D4: CCJ
A5: CEG | B5: =SUMPRODUCT(('Returns & Risk'!B4:B23-AVERAGE('Returns & Risk'!B4:B23)),('Returns & Risk'!B4:B23-AVERAGE('Returns & Risk'!B4:B23)))/19 | C5: =SUMPRODUCT(('Returns & Risk'!B4:B23-AVERAGE('Returns & Risk'!B4:B23)),('Returns & Risk'!C4:C23-AVERAGE('Returns & Risk'!C4:C23)))/19 | D5: =SUMPRODUCT(('Returns & Risk'!B4:B23-AVERAGE('Returns & Risk'!B4:B23)),('Returns & Risk'!D4:D23-AVERAGE('Returns & Risk'!D4:D23)))/19
A6: VST | B6: =SUMPRODUCT(('Returns & Risk'!C4:C23-AVERAGE('Returns & Risk'!C4:C23)),('Returns & Risk'!B4:B23-AVERAGE('Returns & Risk'!B4:B23)))/19 | C6: =SUMPRODUCT(('Returns & Risk'!C4:C23-AVERAGE('Returns & Risk'!C4:C23)),('Returns & Risk'!C4:C23-AVERAGE('Returns & Risk'!C4:C23)))/19 | D6: =SUMPRODUCT(('Returns & Risk'!C4:C23-AVERAGE('Returns & Risk'!C4:C23)),('Returns & Risk'!D4:D23-AVERAGE('Returns & Risk'!D4:D23)))/19
A7: CCJ | B7: =SUMPRODUCT(('Returns & Risk'!D4:D23-AVERAGE('Returns & Risk'!D4:D23)),('Returns & Risk'!B4:B23-AVERAGE('Returns & Risk'!B4:B23)))/19 | C7: =SUMPRODUCT(('Returns & Risk'!D4:D23-AVERAGE('Returns & Risk'!D4:D23)),('Returns & Risk'!C4:C23-AVERAGE('Returns & Risk'!C4:C23)))/19 | D7: =SUMPRODUCT(('Returns & Risk'!D4:D23-AVERAGE('Returns & Risk'!D4:D23)),('Returns & Risk'!D4:D23-AVERAGE('Returns & Risk'!D4:D23)))/19
A10: EFFICIENT-FRONTIER GRID (10% weight steps) + NAMED PORTFOLIOS
A11: w(CEG) | B11: w(VST) | C11: w(CCJ) | D11: Port. Return | E11: Port. Vol | F11: Sharpe
A12: 0 | B12: 0 | C12: 1 | D12: =A12*'Returns & Risk'!B55+B12*'Returns & Risk'!C55+C12*'Returns & Risk'!D55 | E12: =SQRT(A12^2*$B$5*12 + B12^2*$C$6*12 + C12^2*$D$7*12 + 2*A12*B12*$C$5*12 + 2*A12*C12*$D$5*12 + 2*B12*C12*$D$6*12) | F12: =(D12-'Returns & Risk'!$B$52)/E12
A13: 0 | B13: 0.1 | C13: 0.9 | D13: =A13*'Returns & Risk'!B55+B13*'Returns & Risk'!C55+C13*'Returns & Risk'!D55 | E13: =SQRT(A13^2*$B$5*12 + B13^2*$C$6*12 + C13^2*$D$7*12 + 2*A13*B13*$C$5*12 + 2*A13*C13*$D$5*12 + 2*B13*C13*$D$6*12) | F13: =(D13-'Returns & Risk'!$B$52)/E13
A14: 0 | B14: 0.2 | C14: 0.8 | D14: =A14*'Returns & Risk'!B55+B14*'Returns & Risk'!C55+C14*'Returns & Risk'!D55 | E14: =SQRT(A14^2*$B$5*12 + B14^2*$C$6*12 + C14^2*$D$7*12 + 2*A14*B14*$C$5*12 + 2*A14*C14*$D$5*12 + 2*B14*C14*$D$6*12) | F14: =(D14-'Returns & Risk'!$B$52)/E14
A15: 0 | B15: 0.3 | C15: 0.7 | D15: =A15*'Returns & Risk'!B55+B15*'Returns & Risk'!C55+C15*'Returns & Risk'!D55 | E15: =SQRT(A15^2*$B$5*12 + B15^2*$C$6*12 + C15^2*$D$7*12 + 2*A15*B15*$C$5*12 + 2*A15*C15*$D$5*12 + 2*B15*C15*$D$6*12) | F15: =(D15-'Returns & Risk'!$B$52)/E15
A16: 0 | B16: 0.4 | C16: 0.6 | D16: =A16*'Returns & Risk'!B55+B16*'Returns & Risk'!C55+C16*'Returns & Risk'!D55 | E16: =SQRT(A16^2*$B$5*12 + B16^2*$C$6*12 + C16^2*$D$7*12 + 2*A16*B16*$C$5*12 + 2*A16*C16*$D$5*12 + 2*B16*C16*$D$6*12) | F16: =(D16-'Returns & Risk'!$B$52)/E16
A17: 0 | B17: 0.5 | C17: 0.5 | D17: =A17*'Returns & Risk'!B55+B17*'Returns & Risk'!C55+C17*'Returns & Risk'!D55 | E17: =SQRT(A17^2*$B$5*12 + B17^2*$C$6*12 + C17^2*$D$7*12 + 2*A17*B17*$C$5*12 + 2*A17*C17*$D$5*12 + 2*B17*C17*$D$6*12) | F17: =(D17-'Returns & Risk'!$B$52)/E17
A18: 0 | B18: 0.6 | C18: 0.4 | D18: =A18*'Returns & Risk'!B55+B18*'Returns & Risk'!C55+C18*'Returns & Risk'!D55 | E18: =SQRT(A18^2*$B$5*12 + B18^2*$C$6*12 + C18^2*$D$7*12 + 2*A18*B18*$C$5*12 + 2*A18*C18*$D$5*12 + 2*B18*C18*$D$6*12) | F18: =(D18-'Returns & Risk'!$B$52)/E18
A19: 0 | B19: 0.7 | C19: 0.3 | D19: =A19*'Returns & Risk'!B55+B19*'Returns & Risk'!C55+C19*'Returns & Risk'!D55 | E19: =SQRT(A19^2*$B$5*12 + B19^2*$C$6*12 + C19^2*$D$7*12 + 2*A19*B19*$C$5*12 + 2*A19*C19*$D$5*12 + 2*B19*C19*$D$6*12) | F19: =(D19-'Returns & Risk'!$B$52)/E19
A20: 0 | B20: 0.8 | C20: 0.2 | D20: =A20*'Returns & Risk'!B55+B20*'Returns & Risk'!C55+C20*'Returns & Risk'!D55 | E20: =SQRT(A20^2*$B$5*12 + B20^2*$C$6*12 + C20^2*$D$7*12 + 2*A20*B20*$C$5*12 + 2*A20*C20*$D$5*12 + 2*B20*C20*$D$6*12) | F20: =(D20-'Returns & Risk'!$B$52)/E20
A21: 0 | B21: 0.9 | C21: 0.1 | D21: =A21*'Returns & Risk'!B55+B21*'Returns & Risk'!C55+C21*'Returns & Risk'!D55 | E21: =SQRT(A21^2*$B$5*12 + B21^2*$C$6*12 + C21^2*$D$7*12 + 2*A21*B21*$C$5*12 + 2*A21*C21*$D$5*12 + 2*B21*C21*$D$6*12) | F21: =(D21-'Returns & Risk'!$B$52)/E21
A22: 0 | B22: 1 | C22: 0 | D22: =A22*'Returns & Risk'!B55+B22*'Returns & Risk'!C55+C22*'Returns & Risk'!D55 | E22: =SQRT(A22^2*$B$5*12 + B22^2*$C$6*12 + C22^2*$D$7*12 + 2*A22*B22*$C$5*12 + 2*A22*C22*$D$5*12 + 2*B22*C22*$D$6*12) | F22: =(D22-'Returns & Risk'!$B$52)/E22
A23: 0.1 | B23: 0 | C23: 0.9 | D23: =A23*'Returns & Risk'!B55+B23*'Returns & Risk'!C55+C23*'Returns & Risk'!D55 | E23: =SQRT(A23^2*$B$5*12 + B23^2*$C$6*12 + C23^2*$D$7*12 + 2*A23*B23*$C$5*12 + 2*A23*C23*$D$5*12 + 2*B23*C23*$D$6*12) | F23: =(D23-'Returns & Risk'!$B$52)/E23
A24: 0.1 | B24: 0.1 | C24: 0.8 | D24: =A24*'Returns & Risk'!B55+B24*'Returns & Risk'!C55+C24*'Returns & Risk'!D55 | E24: =SQRT(A24^2*$B$5*12 + B24^2*$C$6*12 + C24^2*$D$7*12 + 2*A24*B24*$C$5*12 + 2*A24*C24*$D$5*12 + 2*B24*C24*$D$6*12) | F24: =(D24-'Returns & Risk'!$B$52)/E24
A25: 0.1 | B25: 0.2 | C25: 0.7 | D25: =A25*'Returns & Risk'!B55+B25*'Returns & Risk'!C55+C25*'Returns & Risk'!D55 | E25: =SQRT(A25^2*$B$5*12 + B25^2*$C$6*12 + C25^2*$D$7*12 + 2*A25*B25*$C$5*12 + 2*A25*C25*$D$5*12 + 2*B25*C25*$D$6*12) | F25: =(D25-'Returns & Risk'!$B$52)/E25
A26: 0.1 | B26: 0.3 | C26: 0.6 | D26: =A26*'Returns & Risk'!B55+B26*'Returns & Risk'!C55+C26*'Returns & Risk'!D55 | E26: =SQRT(A26^2*$B$5*12 + B26^2*$C$6*12 + C26^2*$D$7*12 + 2*A26*B26*$C$5*12 + 2*A26*C26*$D$5*12 + 2*B26*C26*$D$6*12) | F26: =(D26-'Returns & Risk'!$B$52)/E26
A27: 0.1 | B27: 0.4 | C27: 0.5 | D27: =A27*'Returns & Risk'!B55+B27*'Returns & Risk'!C55+C27*'Returns & Risk'!D55 | E27: =SQRT(A27^2*$B$5*12 + B27^2*$C$6*12 + C27^2*$D$7*12 + 2*A27*B27*$C$5*12 + 2*A27*C27*$D$5*12 + 2*B27*C27*$D$6*12) | F27: =(D27-'Returns & Risk'!$B$52)/E27
A28: 0.1 | B28: 0.5 | C28: 0.4 | D28: =A28*'Returns & Risk'!B55+B28*'Returns & Risk'!C55+C28*'Returns & Risk'!D55 | E28: =SQRT(A28^2*$B$5*12 + B28^2*$C$6*12 + C28^2*$D$7*12 + 2*A28*B28*$C$5*12 + 2*A28*C28*$D$5*12 + 2*B28*C28*$D$6*12) | F28: =(D28-'Returns & Risk'!$B$52)/E28
A29: 0.1 | B29: 0.6 | C29: 0.3 | D29: =A29*'Returns & Risk'!B55+B29*'Returns & Risk'!C55+C29*'Returns & Risk'!D55 | E29: =SQRT(A29^2*$B$5*12 + B29^2*$C$6*12 + C29^2*$D$7*12 + 2*A29*B29*$C$5*12 + 2*A29*C29*$D$5*12 + 2*B29*C29*$D$6*12) | F29: =(D29-'Returns & Risk'!$B$52)/E29
A30: 0.1 | B30: 0.7 | C30: 0.2 | D30: =A30*'Returns & Risk'!B55+B30*'Returns & Risk'!C55+C30*'Returns & Risk'!D55 | E30: =SQRT(A30^2*$B$5*12 + B30^2*$C$6*12 + C30^2*$D$7*12 + 2*A30*B30*$C$5*12 + 2*A30*C30*$D$5*12 + 2*B30*C30*$D$6*12) | F30: =(D30-'Returns & Risk'!$B$52)/E30
A31: 0.1 | B31: 0.8 | C31: 0.1 | D31: =A31*'Returns & Risk'!B55+B31*'Returns & Risk'!C55+C31*'Returns & Risk'!D55 | E31: =SQRT(A31^2*$B$5*12 + B31^2*$C$6*12 + C31^2*$D$7*12 + 2*A31*B31*$C$5*12 + 2*A31*C31*$D$5*12 + 2*B31*C31*$D$6*12) | F31: =(D31-'Returns & Risk'!$B$52)/E31
A32: 0.1 | B32: 0.9 | C32: 0 | D32: =A32*'Returns & Risk'!B55+B32*'Returns & Risk'!C55+C32*'Returns & Risk'!D55 | E32: =SQRT(A32^2*$B$5*12 + B32^2*$C$6*12 + C32^2*$D$7*12 + 2*A32*B32*$C$5*12 + 2*A32*C32*$D$5*12 + 2*B32*C32*$D$6*12) | F32: =(D32-'Returns & Risk'!$B$52)/E32
A33: 0.2 | B33: 0 | C33: 0.8 | D33: =A33*'Returns & Risk'!B55+B33*'Returns & Risk'!C55+C33*'Returns & Risk'!D55 | E33: =SQRT(A33^2*$B$5*12 + B33^2*$C$6*12 + C33^2*$D$7*12 + 2*A33*B33*$C$5*12 + 2*A33*C33*$D$5*12 + 2*B33*C33*$D$6*12) | F33: =(D33-'Returns & Risk'!$B$52)/E33
A34: 0.2 | B34: 0.1 | C34: 0.7 | D34: =A34*'Returns & Risk'!B55+B34*'Returns & Risk'!C55+C34*'Returns & Risk'!D55 | E34: =SQRT(A34^2*$B$5*12 + B34^2*$C$6*12 + C34^2*$D$7*12 + 2*A34*B34*$C$5*12 + 2*A34*C34*$D$5*12 + 2*B34*C34*$D$6*12) | F34: =(D34-'Returns & Risk'!$B$52)/E34
A35: 0.2 | B35: 0.2 | C35: 0.6 | D35: =A35*'Returns & Risk'!B55+B35*'Returns & Risk'!C55+C35*'Returns & Risk'!D55 | E35: =SQRT(A35^2*$B$5*12 + B35^2*$C$6*12 + C35^2*$D$7*12 + 2*A35*B35*$C$5*12 + 2*A35*C35*$D$5*12 + 2*B35*C35*$D$6*12) | F35: =(D35-'Returns & Risk'!$B$52)/E35
A36: 0.2 | B36: 0.3 | C36: 0.5 | D36: =A36*'Returns & Risk'!B55+B36*'Returns & Risk'!C55+C36*'Returns & Risk'!D55 | E36: =SQRT(A36^2*$B$5*12 + B36^2*$C$6*12 + C36^2*$D$7*12 + 2*A36*B36*$C$5*12 + 2*A36*C36*$D$5*12 + 2*B36*C36*$D$6*12) | F36: =(D36-'Returns & Risk'!$B$52)/E36
A37: 0.2 | B37: 0.4 | C37: 0.4 | D37: =A37*'Returns & Risk'!B55+B37*'Returns & Risk'!C55+C37*'Returns & Risk'!D55 | E37: =SQRT(A37^2*$B$5*12 + B37^2*$C$6*12 + C37^2*$D$7*12 + 2*A37*B37*$C$5*12 + 2*A37*C37*$D$5*12 + 2*B37*C37*$D$6*12) | F37: =(D37-'Returns & Risk'!$B$52)/E37
A38: 0.2 | B38: 0.5 | C38: 0.3 | D38: =A38*'Returns & Risk'!B55+B38*'Returns & Risk'!C55+C38*'Returns & Risk'!D55 | E38: =SQRT(A38^2*$B$5*12 + B38^2*$C$6*12 + C38^2*$D$7*12 + 2*A38*B38*$C$5*12 + 2*A38*C38*$D$5*12 + 2*B38*C38*$D$6*12) | F38: =(D38-'Returns & Risk'!$B$52)/E38
A39: 0.2 | B39: 0.6 | C39: 0.2 | D39: =A39*'Returns & Risk'!B55+B39*'Returns & Risk'!C55+C39*'Returns & Risk'!D55 | E39: =SQRT(A39^2*$B$5*12 + B39^2*$C$6*12 + C39^2*$D$7*12 + 2*A39*B39*$C$5*12 + 2*A39*C39*$D$5*12 + 2*B39*C39*$D$6*12) | F39: =(D39-'Returns & Risk'!$B$52)/E39
A40: 0.2 | B40: 0.7 | C40: 0.1 | D40: =A40*'Returns & Risk'!B55+B40*'Returns & Risk'!C55+C40*'Returns & Risk'!D55 | E40: =SQRT(A40^2*$B$5*12 + B40^2*$C$6*12 + C40^2*$D$7*12 + 2*A40*B40*$C$5*12 + 2*A40*C40*$D$5*12 + 2*B40*C40*$D$6*12) | F40: =(D40-'Returns & Risk'!$B$52)/E40
A41: 0.2 | B41: 0.8 | C41: 0 | D41: =A41*'Returns & Risk'!B55+B41*'Returns & Risk'!C55+C41*'Returns & Risk'!D55 | E41: =SQRT(A41^2*$B$5*12 + B41^2*$C$6*12 + C41^2*$D$7*12 + 2*A41*B41*$C$5*12 + 2*A41*C41*$D$5*12 + 2*B41*C41*$D$6*12) | F41: =(D41-'Returns & Risk'!$B$52)/E41
A42: 0.3 | B42: 0 | C42: 0.7 | D42: =A42*'Returns & Risk'!B55+B42*'Returns & Risk'!C55+C42*'Returns & Risk'!D55 | E42: =SQRT(A42^2*$B$5*12 + B42^2*$C$6*12 + C42^2*$D$7*12 + 2*A42*B42*$C$5*12 + 2*A42*C42*$D$5*12 + 2*B42*C42*$D$6*12) | F42: =(D42-'Returns & Risk'!$B$52)/E42
A43: 0.3 | B43: 0.1 | C43: 0.6 | D43: =A43*'Returns & Risk'!B55+B43*'Returns & Risk'!C55+C43*'Returns & Risk'!D55 | E43: =SQRT(A43^2*$B$5*12 + B43^2*$C$6*12 + C43^2*$D$7*12 + 2*A43*B43*$C$5*12 + 2*A43*C43*$D$5*12 + 2*B43*C43*$D$6*12) | F43: =(D43-'Returns & Risk'!$B$52)/E43
...

Sheet Monte Carlo
A1: MONTE CARLO SIMULATION — 12-Month Portfolio Outcomes (10,000 paths)
A2: Pre-computed by src/monte_carlo.py (seed=42, multivariate-normal monthly returns fit to the 20-month sample, 40/35/25 CEG/VST/CCJ weights). Re-run that script to refresh these values — they are NOT live Excel formulas. See Cover tab for method and limitations.
A4: SIMULATION SUMMARY (terminal, 12-month)
A5: Simulations run | B5: 10000
A6: Mean terminal return | B6: 0.14080432
A7: Median terminal return | B7: 0.059217967
A8: Std dev, terminal return | B8: 0.47485366
A9: Simulated VaR 95% (12-mo) | B9: -0.46093305
A10: Simulated VaR 99% (12-mo) | B10: -0.59521904
A11: Simulated CVaR 95% (12-mo) | B11: -0.54348031
A12: Simulated CVaR 99% (12-mo) | B12: -0.64105899
A13: P(loss) over 12 months | B13: 0.4433
A14: P(loss > 10%) over 12 months | B14: 0.3483
A15: P(gain > 25%) over 12 months | B15: 0.3416
A17: PERCENTILE FAN — PORTFOLIO INDEX PATH (start = 1.00)
A18: MONTH | B18: P5 | C18: P10 | D18: P25 | E18: P50 | F18: P75 | G18: P90 | H18: P95
A19: 1 | B19: 0.81467212 | C19: 0.85891466 | D19: 0.93076021 | E19: 1.008659 | F19: 1.0864234 | G19: 1.1573641 | H19: 1.202851
A20: 2 | B20: 0.75768959 | C20: 0.81054429 | D20: 0.90501236 | E20: 1.0142455 | F20: 1.1271879 | G20: 1.2339478 | H20: 1.3042724
A21: 3 | B21: 0.719028 | C21: 0.77688069 | D21: 0.88764659 | E21: 1.0196384 | F21: 1.1596616 | G21: 1.3000281 | H21: 1.3917145
A22: 4 | B22: 0.68609507 | C22: 0.74933573 | D22: 0.87017162 | E22: 1.0230179 | F22: 1.186727 | G22: 1.35665 | H22: 1.4725797
A23: 5 | B23: 0.65964867 | C23: 0.73076903 | D23: 0.8588482 | E23: 1.024066 | F23: 1.2126684 | G23: 1.4021773 | H23: 1.5393979
A24: 6 | B24: 0.64024053 | C24: 0.71341518 | D24: 0.84931864 | E24: 1.0269578 | F24: 1.2383594 | G24: 1.4609552 | H24: 1.6038839
A25: 7 | B25: 0.61757368 | C25: 0.69516938 | D25: 0.83741643 | E25: 1.0309813 | F25: 1.2594024 | G25: 1.5080675 | H25: 1.6796351
A26: 8 | B26: 0.59779513 | C26: 0.67605778 | D26: 0.82674212 | E26: 1.0327033 | F26: 1.2856065 | G26: 1.5607936 | H26: 1.7562775
A27: 9 | B27: 0.57706381 | C27: 0.6619359 | D27: 0.82140869 | E27: 1.0394332 | F27: 1.3156543 | G27: 1.6069083 | H27: 1.8135761
A28: 10 | B28: 0.55993769 | C28: 0.6493247 | D28: 0.81215467 | E28: 1.0436114 | F28: 1.3437827 | G28: 1.6609348 | H28: 1.8989955
A29: 11 | B29: 0.55014362 | C29: 0.63832158 | D29: 0.8048752 | E29: 1.0517199 | F29: 1.3737857 | G29: 1.7207661 | H29: 1.9662483
A30: 12 | B30: 0.53906695 | C30: 0.61770051 | D30: 0.79927257 | E30: 1.059218 | F30: 1.3884301 | G30: 1.7580563 | H30: 2.0332699
A32: TERMINAL RETURN DISTRIBUTION (histogram, 30 bins)
A33: Bin (left edge) | B33: Frequency
A34: -0.81334 | B34: 0.0053
A35: -0.62376398 | B35: 0.0594
A36: -0.43418795 | B36: 0.1433
A37: -0.24461192 | B37: 0.1821
A38: -0.055035895 | B38: 0.178
A39: 0.13454013 | B39: 0.1431
A40: 0.32411616 | B40: 0.1039
A41: 0.51369219 | B41: 0.0704
A42: 0.70326821 | B42: 0.0445
A43: 0.89284424 | B43: 0.0261
...

Sheet CEG Deep Dive
A1: CEG — Constellation Energy Corporation
A2: Sector: Utilities — Independent Power Producers | Largest U.S. nuclear fleet operator (~31,676 MW) | Baltimore, MD
A4: KEY FUNDAMENTALS
A5: Price (2026-10-01) | B5: $264.58
A6: Market capitalization | B6: ~$92.3B
A7: 52-week range | B7: $228.63 – $412.70
A8: P/E ratio (TTM) | B8: 25.5x
A9: Forward P/E | B9: 21.4x
A10: EPS (TTM) | B10: $10.24 – $10.33
A11: Revenue (TTM) | B11: $31.27B (+26.0% YoY)
A12: Dividend yield | B12: 0.64%
A13: Beta (5Y monthly) | B13: 1.12
A14: FY2026 EPS guidance (raised) | B14: $11.50 – $12.50
A15: Analyst consensus | B15: Buy / Strong Buy
A16: Avg. 12-mo price target | B16: ~$379 (BMO, Aug-2026)
A18: TECHNICAL PICTURE
A19: Trend status | B19: Below 200-day SMA; lower half of 52-wk range
A20: Price vs. 52-wk high/low | B20: -35.9% / +15.7%
A21: 1-year price return | B21: -20.3%
A22: Key support / resistance | B22: ~$250 support / ~$310–330 resistance
A25: RECENT QUARTERLY EARNINGS HISTORY
A26: Quarter | B26: Report Date | C26: EPS Est. | D26: EPS Actual | E26: Surprise | F26: Price Reaction
A27: Q2 2026 | B27: 2026-08-06 | C27: $2.28 | D27: $2.55 | E27: +11.7% | F27: Guidance raised to $11.50-12.50
A28: Q1 2026 | B28: 2026-05-11 | C28: $2.60 | D28: $2.74 | E28: +5.3% | F28: -1.3% (1-day)
A29: Q4 2025 | B29: 2026-02-24 | C29: N/A | D29: $2.30 | E29: +2.4% | F29: +6.4% (1-day)
A30: Q3 2025 | B30: 2025-11-07 | C30: $3.13 | D30: $3.04 | E30: -2.9% | F30: +2.0% (1-day)
A32: CATALYST CALENDAR & RECENT EVENTS (chronological)
A33: 2026-08-06 | B33: Q2 2026 results; FY26 guidance raised to $11.50-12.50; 920 MW of new long-term PPAs signed.
A34: 2026 (ongoing) | B34: FERC/NRC approvals advance Crane Clean Energy Center (former TMI Unit 1) restart for Microsoft.
A35: 2026 (ongoing) | B35: Calpine acquisition ($16.4B) integration; divesting Brazos Valley + 4.4GW PJM assets to LS Power for DOJ clearance.
A36: 2026-11-09 | B36: Q3 2026 earnings (confirmed). Consensus EPS $3.65–$3.67.
A38: BULL CASE
A39: ✓ Largest U.S. nuclear fleet = irreplaceable carbon-free baseload exactly as hyperscalers sign 20-yr PPAs for that profile.
A40: ✓ Guidance raised twice in 2026 even as the stock sits ~36% below its Oct-2025 high — a valuation reset, not a broken thesis.
A42: BEAR CASE / RISKS
A43: ⚠ Premium multiple (25x+ TTM) for a utility, even after the pullback.
A44: ⚠ Large, complex Calpine integration with forced divestitures still in progress; PJM market-design intervention risk sector-wide.
A46: Sources: SEC EDGAR 8-K, TipRanks, StockAnalysis.com, Yahoo Finance — retrieved 2026-10-01.

Sheet VST Deep Dive
A1: VST — Vistra Corp.
A2: Sector: Utilities — Independent Power Producers | Integrated retail + generation (~39GW) | Irving, TX
A4: KEY FUNDAMENTALS
A5: Price (2026-10-01) | B5: $139.05
A6: Market capitalization | B6: ~$46.4B
A7: 52-week range | B7: $132.66 – $217.10
A8: P/E ratio (TTM) | B8: 21.5x – 23.8x
A9: EPS (TTM) | B9: $6.00
A10: Revenue (FY2025) | B10: $17.74B (+3.0% YoY)
A11: Dividend yield | B11: 0.65%
A12: Beta (5Y monthly, reported) | B12: 1.41 (cross-provider range 0.4–1.9)
A13: FY2026 adj. EBITDA guidance | B13: $6.8B – $7.6B (reaffirmed)
A14: Credit rating | B14: BBB- (Fitch upgrade, Mar-2026)
A15: Analyst consensus | B15: Strong Buy
A16: Avg. 12-mo price target | B16: ~$217.58 (+54.5% implied)
A18: TECHNICAL PICTURE
A19: Trend status | B19: Downtrend since Aug-2025 ($217) to ~$139
A20: Price vs. 52-wk high/low | B20: -36.0% / +4.8%
A21: 1-year price return | B21: -32.4%
A22: Key support / resistance | B22: ~$132–138 support / ~$160–175 resistance
A25: RECENT QUARTERLY EARNINGS HISTORY
A26: Quarter | B26: Report Date | C26: EPS Est. | D26: EPS Actual | E26: Surprise | F26: Price Reaction
A27: Q2 2026 | B27: 2026-08-07 | C27: N/A | D27: N/A | E27: N/A | F27: YTD adj. EBITDA $3.261B vs $2.589B PY
A28: Q1 2026 | B28: 2026-05-11 | C28: N/A | D28: N/A | E28: Record Q1 EBITDA | F28: +5% premarket
A29: FY2025 | B29: 2026-02 (approx.) | C29: N/A | D29: $752M net income | E29: -69.5% YoY | F29: Weather/deal-related noise
A30: Q3 2025 | B30: 2025-11-06 | C30: N/A | D30: N/A | E30: N/A | F30: -6.1% (1-day)
A32: CATALYST CALENDAR & RECENT EVENTS (chronological)
A33: 2026-01-12 | B33: 20-year, 2.6 GW nuclear PPA with Meta — flagship zero-carbon long-duration contract.
A34: 2026-01-15 | B34: PJM market-intervention headline risk — shares fell ~9% on affordability-regulation reports.
A35: 2026-03 | B35: Fitch upgraded Vistra to investment grade (BBB-).
A36: 2026 H2 (pending) | B36: Cogentrix gas portfolio acquisition (5,500 MW) targeted to close; not yet in guidance.
A37: 2026-11-06 | B37: Q3 2026 earnings (confirmed) — first quarter with potential Cogentrix commentary.
A39: BULL CASE
A40: ✓ Purest merchant-power / direct-hyperscaler-PPA exposure of the three (Meta 2.6GW/20-yr deal).
A41: ✓ Investment-grade upgrade lowers financing cost during an active M&A phase; highest analyst conviction of the group (~55% implied upside).
A43: BEAR CASE / RISKS
A44: ⚠ Most exposed of the three to PJM/ERCOT regulatory intervention — already proven with a 9% single-day drop.
A45: ⚠ Merchant power economics are inherently more volatile than regulated/contracted revenue; Cogentrix deal unclosed.
A47: Sources: StockAnalysis.com, TradingView, Robinhood, Morningstar, PR Newswire — retrieved 2026-10-01.

Sheet CCJ Deep Dive
A1: CCJ — Cameco Corporation
A2: Sector: Energy — Uranium Mining & Nuclear Fuel Cycle | Uranium, Fuel Services, Westinghouse (49%) | Saskatoon, Canada
A4: KEY FUNDAMENTALS
A5: Price (2026-10-01) | B5: $87.39
A6: Market capitalization | B6: ~$37.8B
A7: 52-week range | B7: $77.70 – $135.24
A8: P/E ratio (TTM) | B8: ~147x–152x (thin TTM earnings)
A9: EPS (TTM) | B9: $0.57
A10: Revenue (FY2025) | B10: $3.48B (+11.0% YoY)
A11: Net income (FY2025) | B11: $589.6M (+243.1% YoY)
A12: Dividend yield | B12: 0.20%
A13: Beta (5Y monthly) | B13: 1.01
A14: Analyst consensus | B14: Buy / Moderate Buy
A15: Avg. 12-mo price target | B15: $127.77 – $148.68 (wide dispersion)
A17: TECHNICAL PICTURE
A18: Trend status | B18: Round-trip: $78 (Apr-25) → $135 (Oct-25/Jan-26) → ~$87 now
A19: Price vs. 52-wk high/low | B19: -35.4% / +12.5%
A20: 1-year price return | B20: -4.2% (highly path-dependent)
A21: Key support / resistance | B21: ~$86–90 support / ~$110–123 resistance
A24: RECENT QUARTERLY EARNINGS HISTORY
A25: Quarter | B25: Report Date | C25: EPS Est. | D25: EPS Actual | E25: Surprise | F25: Price Reaction
A26: Q2 2026 | B26: 2026-07-31 | C26: $0.26 | D26: $0.13 | E26: -50% to -64% | F26: -2.1% to -3.2% (1-day)
A27: Q1 2026 | B27: 2026-05-05 | C27: $0.25–$0.36 | D27: $0.22–$0.34 | E27: mixed | F27: -3.2% on initial miss
A28: Q4 2025 | B28: 2026-02-13 | C28: $0.32 | D28: $0.33–$0.36 | E28: ~0–+28.6% | F28: N/A
A29: Q3 2025 | B29: 2025-11-05 | C29: $0.23 | D29: $0.05 | E29: -78.3% | F29: N/A
A31: CATALYST CALENDAR & RECENT EVENTS (chronological)
A32: 2026-07-31 | B32: Q2 2026 EPS $0.13 vs $0.26 est. (miss); shares drifted +10.8% higher over the following 33 days.
A33: 2026 (ongoing) | B33: Westinghouse (49%-owned) IPO speculation — potential embedded-value unlock.
A34: 2026-10-30 (est.) | B34: Q3 2026 earnings — date not yet formally confirmed (alt. estimate Nov 4).
A35: Structural | B35: Global uranium supply deficit from AI-driven electrification demand + a decade of underinvestment.
A37: BULL CASE
A38: ✓ Purest upstream fuel-cycle exposure of the three; FY2025 net income +243% YoY shows real operating leverage emerging.
A39: ✓ Westinghouse stake is a legitimate, not-fully-priced-in embedded-value catalyst.
A41: BEAR CASE / RISKS
A42: ⚠ Highest volatility of the three and a demanding valuation (147x+ TTM P/E) with little room for further misses.
A43: ⚠ Two of the last four quarters were significant EPS misses — a recurring pattern, not a one-off; next earnings date unconfirmed.
A45: Sources: MarketChameleon, StockAnalysis.com, MarketBeat, Yahoo Finance — retrieved 2026-10-01.

Sheet Catalyst Calendar
A1: CONSOLIDATED CATALYST CALENDAR — Oct 2026 through Q1 2027
A2: Date | B2: Ticker | C2: Event | D2: Type | E2: Confirmed?
A3: 2026-10-01 | B3: ALL | C3: Report-date valuation snapshot; all fundamentals in this workbook as-of this date. | D3: Reference | E3: N/A
A4: 2026-10-30 | B4: CCJ | C4: Q3 2026 earnings (estimated — not formally confirmed; alt. tracker estimate Nov 4). | D4: Earnings | E4: Estimated
A5: 2026-11-06 | B5: VST | C5: Q3 2026 earnings. First full quarter with potential Cogentrix commentary. | D5: Earnings | E5: Confirmed
A6: 2026-11-09 | B6: CEG | C6: Q3 2026 earnings. Consensus EPS $3.65–$3.67. | D6: Earnings | E6: Confirmed
A7: 2026 H2 (TBD) | B7: VST | C7: Cogentrix gas portfolio (5,500 MW) acquisition targeted to close. | D7: M&A / Closing | E7: Pending
A8: 2026 (ongoing) | B8: CEG | C8: Crane Clean Energy Center restart progress (FERC/NRC approvals granted). | D8: Regulatory | E8: In progress
A9: 2026 (ongoing) | B9: CEG | C9: Calpine integration; Brazos Valley + 4.4GW PJM divestiture to LS Power. | D9: M&A / Regulatory | E9: In progress
A10: 2026 (ongoing) | B10: CCJ | C10: Westinghouse IPO speculation — potential embedded-value unlock. | D10: Corporate action | E10: Speculative
A11: 2026 (ongoing) | B11: ALL | C11: PJM/ERCOT affordability intervention risk — VST most exposed, CEG moderate, CCJ least. | D11: Regulatory risk | E11: Monitoring
A12: 2026 (ongoing) | B12: CCJ | C12: Global uranium structural deficit narrative vs. supply growth. | D12: Macro / Structural | E12: Ongoing
A13: 2027 Q1 (est.) | B13: ALL | C13: Q4 2026 earnings across all three — first full read on FY2026 guidance delivery and FY2027 initial guides. | D13: Earnings | E13: Estimated

Sheet Recommendation
A1: PORTFOLIO RECOMMENDATION — Optimizer & Simulation-Informed
A3: RISK / REWARD SNAPSHOT (live-linked to Returns & Risk)
A4: Metric | B4: CEG | C4: VST | D4: CCJ
A5: Annualized return | B5: ='Returns & Risk'!B55 | C5: ='Returns & Risk'!C55 | D5: ='Returns & Risk'!D55
A6: Annualized volatility | B6: ='Returns & Risk'!B56 | C6: ='Returns & Risk'!C56 | D6: ='Returns & Risk'!D56
A7: Sharpe ratio | B7: ='Returns & Risk'!B64 | C7: ='Returns & Risk'!C64 | D7: ='Returns & Risk'!D64
A8: Sortino ratio | B8: ='Returns & Risk'!B63 | C8: ='Returns & Risk'!C63 | D8: ='Returns & Risk'!D63
A9: Max drawdown (real) | B9: ='Returns & Risk'!B57 | C9: ='Returns & Risk'!C57 | D9: ='Returns & Risk'!D57
A10: Historical VaR 95% (monthly) | B10: ='Returns & Risk'!B60 | C10: ='Returns & Risk'!C60 | D10: ='Returns & Risk'!D60
A11: Historical CVaR 95% (monthly) | B11: ='Returns & Risk'!B62 | C11: ='Returns & Risk'!C62 | D11: ='Returns & Risk'!D62
A13: OPTIMIZER OUTPUT (live-linked to Portfolio Optimization)
A14: Portfolio | B14: w(CEG) | C14: w(VST) | D14: w(CCJ)
A15: Max-Sharpe (optimizer) | B15: ='Portfolio Optimization'!B86 | C15: ='Portfolio Optimization'!C86 | D15: ='Portfolio Optimization'!D86
A16: Min-Volatility (optimizer) | B16: ='Portfolio Optimization'!B87 | C16: ='Portfolio Optimization'!C87 | D16: ='Portfolio Optimization'!D87
A17: Research Recommendation | B17: ='Portfolio Optimization'!A82 | C17: ='Portfolio Optimization'!B82 | D17: ='Portfolio Optimization'!C82
A19: Why we don't just take the optimizer's weights: mean-variance optimization on a 20-observation sample is notoriously unstable — it tends to pile weight into whichever asset happened to have the best trailing Sharpe, which is as much noise as signal at this sample size. The Research Recommendation (40/35/25) deliberately keeps CCJ's weight below both the optimizer's and an equal-weight split, specifically because its earnings unpredictability and valuation are a real, separate risk the optimizer's covariance matrix does not capture. Compare all three rows above before sizing a real position.
A24: 12-MONTH SCENARIO FRAMING (from Monte Carlo simulation, Research Reco weights)
A25: Scenario | B25: Simulated 12-mo return
A26: Bear (5th percentile) | B26: -0.46093305
A27: Below-average (25th pct.) | B27: -0.20072743
A28: Base / median (50th pct.) | B28: 0.059217967
A29: Above-average (75th pct.) | B29: 0.38843006
A30: Bull (95th percentile) | B30: 1.0332699
A32: Distribution-level risk: P(loss) = 44.3% over 12 months; P(loss > 10%) = 34.8%; simulated 95% VaR = -46.1%, 95% CVaR = -54.3% — i.e., in the worst 5% of simulated outcomes, the average loss is roughly -54%. This is the honest tail-risk picture that a single 'bear case' price target does not convey.
A35: BOTTOM LINE
A36: All three names screen Buy-rated with meaningful upside to analyst targets after a broad 2025/2026 sector de-rating. Benchmarked against XLE, CEG and VST's betas and information ratios (Benchmark & Factors tab) show how much of their recent weakness is sector-wide vs. idiosyncratic; the factor table shows real, if imprecise, sensitivity to oil, gas, uranium and rates. The optimizer confirms a barbell shape is reasonable but, on this short sample, would overweight whichever name had the best trailing luck — a classic mean-variance pitfall — which is why the Research Recommendation deliberately underweights the optimizer's top pick relative to its covariance-implied weight. The Monte Carlo simulation replaces a single eyeballed bear/base/bull price with an actual distribution: a ~44% chance of loss over 12 months and a 95% CVaR near -54% at these weights is a real, quantified tail risk, not a footnote. This is a research framework for further diligence, not a trade instruction; position sizing, entry timing, and risk limits should be set per the investor's own mandate and verified against live market data.
A43: DISCLAIMER: All scenario ranges, optimizer output, and Monte Carlo statistics are illustrative, author-generated analysis for portfolio-construction discussion only — not price targets, recommendations, or investment advice. This is not a research report of a registered broker-dealer or investment adviser. See the Cover tab for full methodology and limitations. Consult a licensed financial advisor and verify all data independently before making any investment decision.
